#VRML_SIM R2025a utf8

EXTERNPROTO "https://raw.githubusercontent.com/cyberbotics/webots/R2022b/projects/objects/backgrounds/protos/TexturedBackground.proto"
EXTERNPROTO "https://raw.githubusercontent.com/cyberbotics/webots/R2022b/projects/objects/backgrounds/protos/TexturedBackgroundLight.proto"
EXTERNPROTO "https://raw.githubusercontent.com/cyberbotics/webots/R2022b/projects/objects/floors/protos/CircleArena.proto"
EXTERNPROTO "https://raw.githubusercontent.com/cyberbotics/webots/R2022b/projects/appearances/protos/BrushedAluminium.proto"

WorldInfo {
}
Viewpoint {
  orientation -0.32551252112484813 -0.40020041125993394 0.8566686812404928 4.764226232854815
  position -0.457632332457399 4.528167839859021 3.703340341126822
  follow "robot1"
}
TexturedBackground {
  skybox FALSE
}
TexturedBackgroundLight {
  castShadows FALSE
}
CircleArena {
  radius 3
}
Robot {
  translation 0.84 -0.24 0
  rotation 0 0 1 -1.5707953071795862
  children [
    HingeJoint {
      jointParameters HingeJointParameters {
        axis 0 1 0
        anchor 0 0 0.025
      }
      device [
        RotationalMotor {
          name "left wheel motor"
        }
      ]
      endPoint Solid {
        translation 0 0.045 0.025
        rotation 0 1 0 0
        children [
          DEF WHEEL Pose {
            rotation 1 0 0 1.5707996938995747
            children [
              Shape {
                appearance PBRAppearance {
                  baseColor 1 0 0
                  roughness 1
                  metalness 0
                }
                geometry Cylinder {
                  height 0.01
                  radius 0.025
                }
              }
            ]
          }
        ]
        name "left wheel"
        boundingObject USE WHEEL
        physics Physics {
        }
      }
    }
    HingeJoint {
      jointParameters HingeJointParameters {
        axis 0 1 0
        anchor 0 0 0.025
      }
      device [
        RotationalMotor {
          name "right wheel motor"
        }
      ]
      endPoint Solid {
        translation 0 -0.045 0.025
        rotation 0 1 0 0
        children [
          USE WHEEL
        ]
        name "right wheel"
        boundingObject USE WHEEL
        physics Physics {
        }
      }
    }
    Pose {
      translation 0 0 0.0415
      children [
        Shape {
          appearance PBRAppearance {
            baseColor 0 0 1
            roughness 1
            metalness 0
          }
          geometry DEF BODY Cylinder {
            height 0.08
            radius 0.045
          }
        }
      ]
    }
    DistanceSensor {
      translation 0.042 0.02 0.063
      rotation 0 0 1 0.5236003061004253
      children [
        DEF SENSOR Pose {
          rotation 0 1 0 1.5708
          children [
            Shape {
              appearance PBRAppearance {
                baseColor 1 1 0
                roughness 1
                metalness 0
              }
              geometry Cylinder {
                height 0.004
                radius 0.008
              }
            }
          ]
        }
      ]
      name "ds0"
      lookupTable [
        0 1020 0
        0.05 1020 0
        0.15 0 0
      ]
      numberOfRays 2
      aperture 1
    }
    DistanceSensor {
      translation 0.042 -0.02 0.063
      rotation 0 0 1 -0.5235996938995747
      children [
        USE SENSOR
      ]
      name "ds1"
      lookupTable [
        0 1020 0
        0.05 1020 0
        0.15 0 0
      ]
      numberOfRays 2
      aperture 1
    }
    DistanceSensor {
      translation -0.042 0 0.063
      rotation 0 0 1 3.14159
      children [
        DEF BACK_SENSOR Pose {
          rotation 0 1 0 1.5708
          children [
            Shape {
              appearance PBRAppearance {
                baseColor 0.5 0.5 0.5
                roughness 1
                metalness 0
              }
              geometry Cylinder {
                height 0.004
                radius 0.008
              }
            }
          ]
        }
      ]
      name "back_sensor"
      lookupTable [
        0 1020 0
        0.05 1020 0
        0.5 0 0
      ]
      numberOfRays 2
      aperture 1
    }
    Camera {
      translation -0.042 0 0.063
      rotation 0 0 1 3.14159
      children [
        DEF COLOR_CAMERA Pose {
          rotation 0 1 0 1.5708
          children [
            Shape {
              appearance PBRAppearance {
                baseColor 0.2 0.2 0.2
                roughness 1
                metalness 0
              }
              geometry Cylinder {
                height 0.006
                radius 0.01
              }
            }
          ]
        }
      ]
      name "color_sensor"
      fieldOfView 1.57
      far 1
    }
  ]
  name "robot1"
  boundingObject Pose {
    translation 0 0 0.0415
    children [
      USE BODY
    ]
  }
  physics Physics {
  }
  controller "<extern>"
  controllerArgs [
    "1234"
  ]
}
Robot {
  translation 0.87 0.1 0
  rotation 0 0 1 -1.5707953071795862
  children [
    HingeJoint {
      jointParameters HingeJointParameters {
        axis 0 1 0
        anchor 0 0 0.025
      }
      device [
        RotationalMotor {
          name "left wheel motor"
        }
      ]
      endPoint Solid {
        translation 0 0.045 0.025
        rotation 0 1 0 0
        children [
          DEF WHEEL2 Pose {
            rotation 1 0 0 1.5707996938995747
            children [
              Shape {
                appearance PBRAppearance {
                  baseColor 1 0 0
                  roughness 1
                  metalness 0
                }
                geometry Cylinder {
                  height 0.01
                  radius 0.025
                }
              }
            ]
          }
        ]
        name "left wheel"
        boundingObject USE WHEEL2
        physics Physics {
        }
      }
    }
    HingeJoint {
      jointParameters HingeJointParameters {
        axis 0 1 0
        anchor 0 0 0.025
      }
      device [
        RotationalMotor {
          name "right wheel motor"
        }
      ]
      endPoint Solid {
        translation 0 -0.045 0.025
        rotation 0 1 0 0
        children [
          USE WHEEL2
        ]
        name "right wheel"
        boundingObject USE WHEEL2
        physics Physics {
        }
      }
    }
    Pose {
      translation 0 0 0.0415
      children [
        Shape {
          appearance PBRAppearance {
            baseColor 0 1 0
            roughness 1
            metalness 0
          }
          geometry DEF BODY2 Cylinder {
            height 0.08
            radius 0.045
          }
        }
      ]
    }
    DistanceSensor {
      translation 0.042 0.02 0.063
      rotation 0 0 1 0.5236003061004253
      children [
        DEF SENSOR2 Pose {
          rotation 0 1 0 1.5708
          children [
            Shape {
              appearance PBRAppearance {
                baseColor 1 1 0
                roughness 1
                metalness 0
              }
              geometry Cylinder {
                height 0.004
                radius 0.008
              }
            }
          ]
        }
      ]
      name "ds0"
      lookupTable [
        0 1020 0
        0.05 1020 0
        0.15 0 0
      ]
      numberOfRays 2
      aperture 1
    }
    DistanceSensor {
      translation 0.042 -0.02 0.063
      rotation 0 0 1 -0.5235996938995747
      children [
        USE SENSOR2
      ]
      name "ds1"
      lookupTable [
        0 1020 0
        0.05 1020 0
        0.15 0 0
      ]
      numberOfRays 2
      aperture 1
    }
  ]
  name "robot2"
  boundingObject Pose {
    translation 0 0 0.0415
    children [
      USE BODY2
    ]
  }
  physics Physics {
  }
  controller "<extern>"
  controllerArgs [
    "1235"
  ]
}
Solid {
  translation 1.08406 0.0650552 0.05
  rotation 0 0 1 -0.5233953071795865
  children [
    Shape {
      appearance PBRAppearance {
        baseColor 0.8 0.8 0.8
        roughness 1
        metalness 0
      }
      geometry Mesh {
        url [
          "textures/tilde2.stl"
        ]
      }
    }
  ]
  boundingObject Mesh {
    url [
      "textures/tilde2.stl"
    ]
  }
  physics Physics {
  }
  rotationStep 0.261809
}
